Workbook

Sheet Antigüedad y Vencimiento
A1: PARQUE DE AMBULANCIAS — UTIM · ANTIGÜEDAD Y VENCIMIENTO POR SEGMENTO
A2: Límites vigentes: YPF/O&G = 8 años · VISTA OIL = 5 años · Minería = 3 años · Back Up / Disponible / OOD = 10 años (hab. nacional) · UCI = Excluido · Año de referencia: 2026
A4: Año Patent. | B4: TOTAL UTIM | C4: YPF / O&G (8 años) | E4: VISTA OIL (5 años) | G4: Minería (3 años) | I4: Back Up (10 años) | K4: Disponible (10 años) | M4: OOD (10 años) | O4: UCI (Excluido)
A5: 2017 | B5: 12 | G5: 1 | H5: → 2021 ✗ VENCIDA | I5: 3 | J5: → 2028 ◄ 2028 | K5: 6 | L5: → 2028 ◄ 2028 | M5: 1 | N5: → 2028 ◄ 2028 | O5: 1 | P5: Excluido
A6: 2018 | B6: 2 | C6: 1 | D6: → 2027 ◄ 2027 | K6: 1 | L6: → 2029
A7: 2019 | B7: 25 | C7: 11 | D7: → 2028 ◄ 2028 | E7: 1 | F7: → 2025 ✗ VENCIDA | G7: 4 | H7: → 2023 ✗ VENCIDA | I7: 3 | J7: → 2030 | K7: 5 | L7: → 2030 | O7: 1 | P7: Excluido
A8: 2022 | B8: 7 | G8: 6 | H8: → 2026 ◄ 2026 | I8: 1 | J8: → 2033
A9: 2023 | B9: 17 | C9: 10 | D9: → 2032 | G9: 4 | H9: → 2027 ◄ 2027 | I9: 2 | J9: → 2034 | K9: 1 | L9: → 2034
A10: 2024 | B10: 14 | C10: 1 | D10: → 2033 | E10: 3 | F10: → 2030 | G10: 6 | H10: → 2028 ◄ 2028 | I10: 4 | J10: → 2035
A11: 2025 | B11: 7 | G11: 5 | H11: → 2029 | I11: 1 | J11: → 2036 | M11: 1 | N11: → 2036
A13: TOTAL | B13: 84 | C13: 23 | E13: 4 | G13: 26 | I13: 14 | K13: 13 | M13: 2 | O13: 2
A15: LEYENDA: | B15: ◄ Vence en 2026 — URGENTE | C15: ◄ Vence en 2027 | D15: ◄ Vence en 2028 — PICO | E15: ✗ Ya vencida (acción inmediata) | F15: Vence 2029 en adelante
A18: PLAN DE RENOVACIÓN — UNIDADES A REPONER POR AÑO (sin optimización)
A19: Segmento | B19: TOTAL | C19: 2021 | D19: 2022 | E19: 2023 | F19: 2024 | G19: 2025 | H19: 2026 | I19: 2027 | J19: 2028 | K19: 2029 | L19: 2030 | M19: 2031 | N19: 2032 | O19: 2033 | P19: 2034 | Q19: 2035 | R19: 2036
A20: YPF / O&G (8 años) | B20: 23 | I20: 1 | J20: 11 | N20: 10 | O20: 1
A21: VISTA OIL (5 años) | B21: 4 | G21: 1 | L21: 3
A22: Minería (3 años) | B22: 26 | C22: 1 | E22: 4 | H22: 6 | I22: 4 | J22: 6 | K22: 5
A23: Back Up (10 años) | B23: 14 | J23: 3 | L23: 3 | O23: 1 | P23: 2 | Q23: 4 | R23: 1
A24: Disponible (10 años) | B24: 13 | J24: 6 | K24: 1 | L24: 5 | P24: 1
A25: OOD (10 años) | B25: 2 | J25: 1 | R25: 1
A26: TOTAL GENERAL | B26: 82 | C26: 1 | E26: 4 | G26: 1 | H26: 6 | I26: 5 | J26: 27 | K26: 6 | L26: 11 | N26: 10 | O26: 2 | P26: 3 | Q26: 4 | R26: 2

Sheet Resumen Directorio
A1: FLOTA DE MÓVILES — REGIÓN / CLIENTE × AÑO DE PATENTAMIENTO
A2: =C55&" móviles · "&C26&" UTIM · "&(C53)&" Logística (incluye Otros)" -> 109 móviles · 77 UTIM · 32 Logística (incluye Otros)
A4: ≥9 años (2017) | B4: 7-8 años (2018) | C4: 4-6 años (2019-22) | D4: 2-3 años (2023-24) | E4: ≤1 año (2025)
A5: UTIM — Ambulancias de Traslado Intensivo Móvil
A6: Región | B6: Cliente / Asignación | C6: Total | D6: 2017 | E6: 2018 | F6: 2019 | G6: 2021 | H6: 2022 | I6: 2023 | J6: 2024 | K6: 2025 | L6: Total
A7: Neuquén | B7: YPF | C7: =SUM(D7:K7) -> 24 | D7: =COUNTIFS(TablaMóviles[Región],"UTIM NQN",TablaMóviles[Año],2017,TablaMóviles[Cliente],"YPF") -> 0 | E7: =COUNTIFS(TablaMóviles[Región],"UTIM NQN",TablaMóviles[Año],2018,TablaMóviles[Cliente],"YPF") -> 0 | F7: =COUNTIFS(TablaMóviles[Región],"UTIM NQN",TablaMóviles[Año],2019,TablaMóviles[Cliente],"YPF") -> 11 | G7: =COUNTIFS(TablaMóviles[Región],"UTIM NQN",TablaMóviles[Año],2021,TablaMóviles[Cliente],"YPF") -> 0 | H7: =COUNTIFS(TablaMóviles[Región],"UTIM NQN",TablaMóviles[Año],2022,TablaMóviles[Cliente],"YPF") -> 0 | I7: =COUNTIFS(TablaMóviles[Región],"UTIM NQN",TablaMóviles[Año],2023,TablaMóviles[Cliente],"YPF") -> 10 | J7: =COUNTIFS(TablaMóviles[Región],"UTIM NQN",TablaMóviles[Año],2024,TablaMóviles[Cliente],"YPF") -> 3 | K7: =COUNTIFS(TablaMóviles[Región],"UTIM NQN",TablaMóviles[Año],2025,TablaMóviles[Cliente],"YPF") -> 0 | L7: =SUM(D7:K7) -> 24
B8: Techint | C8: =SUM(D8:K8) -> 4 | D8: =COUNTIFS(TablaMóviles[Región],"UTIM NQN",TablaMóviles[Año],D$6,TablaMóviles[Cliente],"TECHINT") -> 2 | E8: =COUNTIFS(TablaMóviles[Región],"UTIM NQN",TablaMóviles[Año],E$6,TablaMóviles[Cliente],"TECHINT") -> 0 | F8: =COUNTIFS(TablaMóviles[Región],"UTIM NQN",TablaMóviles[Año],F$6,TablaMóviles[Cliente],"TECHINT") -> 2 | G8: =COUNTIFS(TablaMóviles[Región],"UTIM NQN",TablaMóviles[Año],G$6,TablaMóviles[Cliente],"TECHINT") -> 0 | H8: =COUNTIFS(TablaMóviles[Región],"UTIM NQN",TablaMóviles[Año],H$6,TablaMóviles[Cliente],"TECHINT") -> 0 | I8: =COUNTIFS(TablaMóviles[Región],"UTIM NQN",TablaMóviles[Año],I$6,TablaMóviles[Cliente],"TECHINT") -> 0 | J8: =COUNTIFS(TablaMóviles[Región],"UTIM NQN",TablaMóviles[Año],J$6,TablaMóviles[Cliente],"TECHINT") -> 0 | K8: =COUNTIFS(TablaMóviles[Región],"UTIM NQN",TablaMóviles[Año],K$6,TablaMóviles[Cliente],"TECHINT") -> 0 | L8: =SUM(D8:K8) -> 4
B9: Vista Oil | C9: =SUM(D9:K9) -> 4 | D9: =COUNTIFS(TablaMóviles[Región],"UTIM NQN",TablaMóviles[Año],2017,TablaMóviles[Cliente],"VISTA OIL") -> 0 | E9: =COUNTIFS(TablaMóviles[Región],"UTIM NQN",TablaMóviles[Año],2018,TablaMóviles[Cliente],"VISTA OIL") -> 0 | F9: =COUNTIFS(TablaMóviles[Región],"UTIM NQN",TablaMóviles[Año],2019,TablaMóviles[Cliente],"VISTA OIL") -> 1 | G9: =COUNTIFS(TablaMóviles[Región],"UTIM NQN",TablaMóviles[Año],2021,TablaMóviles[Cliente],"VISTA OIL") -> 0 | H9: =COUNTIFS(TablaMóviles[Región],"UTIM NQN",TablaMóviles[Año],2022,TablaMóviles[Cliente],"VISTA OIL") -> 0 | I9: =COUNTIFS(TablaMóviles[Región],"UTIM NQN",TablaMóviles[Año],2023,TablaMóviles[Cliente],"VISTA OIL") -> 0 | J9: =COUNTIFS(TablaMóviles[Región],"UTIM NQN",TablaMóviles[Año],2024,TablaMóviles[Cliente],"VISTA OIL") -> 3 | K9: =COUNTIFS(TablaMóviles[Región],"UTIM NQN",TablaMóviles[Año],2025,TablaMóviles[Cliente],"VISTA OIL") -> 0 | L9: =SUM(D9:K9) -> 4
B10: Aconcagua | C10: =SUM(D10:K10) -> 1 | D10: =COUNTIFS(TablaMóviles[Región],"UTIM NQN",TablaMóviles[Año],2017,TablaMóviles[Cliente],"ACONCAGUA") -> 0 | E10: =COUNTIFS(TablaMóviles[Región],"UTIM NQN",TablaMóviles[Año],2018,TablaMóviles[Cliente],"ACONCAGUA") -> 0 | F10: =COUNTIFS(TablaMóviles[Región],"UTIM NQN",TablaMóviles[Año],2019,TablaMóviles[Cliente],"ACONCAGUA") -> 1 | G10: =COUNTIFS(TablaMóviles[Región],"UTIM NQN",TablaMóviles[Año],2021,TablaMóviles[Cliente],"ACONCAGUA") -> 0 | H10: =COUNTIFS(TablaMóviles[Región],"UTIM NQN",TablaMóviles[Año],2022,TablaMóviles[Cliente],"ACONCAGUA") -> 0 | I10: =COUNTIFS(TablaMóviles[Región],"UTIM NQN",TablaMóviles[Año],2023,TablaMóviles[Cliente],"ACONCAGUA") -> 0 | J10: =COUNTIFS(TablaMóviles[Región],"UTIM NQN",TablaMóviles[Año],2024,TablaMóviles[Cliente],"ACONCAGUA") -> 0 | K10: =COUNTIFS(TablaMóviles[Región],"UTIM NQN",TablaMóviles[Año],2025,TablaMóviles[Cliente],"ACONCAGUA") -> 0 | L10: =SUM(D10:K10) -> 1
B11: Capex | C11: =SUM(D11:K11) -> 1 | D11: =COUNTIFS(TablaMóviles[Región],"UTIM NQN",TablaMóviles[Año],2017,TablaMóviles[Cliente],"CAPEX") -> 0 | E11: =COUNTIFS(TablaMóviles[Región],"UTIM NQN",TablaMóviles[Año],2018,TablaMóviles[Cliente],"CAPEX") -> 0 | F11: =COUNTIFS(TablaMóviles[Región],"UTIM NQN",TablaMóviles[Año],2019,TablaMóviles[Cliente],"CAPEX") -> 0 | G11: =COUNTIFS(TablaMóviles[Región],"UTIM NQN",TablaMóviles[Año],2021,TablaMóviles[Cliente],"CAPEX") -> 0 | H11: =COUNTIFS(TablaMóviles[Región],"UTIM NQN",TablaMóviles[Año],2022,TablaMóviles[Cliente],"CAPEX") -> 0 | I11: =COUNTIFS(TablaMóviles[Región],"UTIM NQN",TablaMóviles[Año],2023,TablaMóviles[Cliente],"CAPEX") -> 1 | J11: =COUNTIFS(TablaMóviles[Región],"UTIM NQN",TablaMóviles[Año],2024,TablaMóviles[Cliente],"CAPEX") -> 0 | K11: =COUNTIFS(TablaMóviles[Región],"UTIM NQN",TablaMóviles[Año],2025,TablaMóviles[Cliente],"CAPEX") -> 0 | L11: =SUM(D11:K11) -> 1
B12: Genneia | C12: =SUM(D12:K12) -> 1 | D12: =COUNTIFS(TablaMóviles[Región],"UTIM NQN",TablaMóviles[Año],2017,TablaMóviles[Cliente],"GENNEIA") -> 1 | E12: =COUNTIFS(TablaMóviles[Región],"UTIM NQN",TablaMóviles[Año],2018,TablaMóviles[Cliente],"GENNEIA") -> 0 | F12: =COUNTIFS(TablaMóviles[Región],"UTIM NQN",TablaMóviles[Año],2019,TablaMóviles[Cliente],"GENNEIA") -> 0 | G12: =COUNTIFS(TablaMóviles[Región],"UTIM NQN",TablaMóviles[Año],2021,TablaMóviles[Cliente],"GENNEIA") -> 0 | H12: =COUNTIFS(TablaMóviles[Región],"UTIM NQN",TablaMóviles[Año],2022,TablaMóviles[Cliente],"GENNEIA") -> 0 | I12: =COUNTIFS(TablaMóviles[Región],"UTIM NQN",TablaMóviles[Año],2023,TablaMóviles[Cliente],"GENNEIA") -> 0 | J12: =COUNTIFS(TablaMóviles[Región],"UTIM NQN",TablaMóviles[Año],2024,TablaMóviles[Cliente],"GENNEIA") -> 0 | K12: =COUNTIFS(TablaMóviles[Región],"UTIM NQN",TablaMóviles[Año],2025,TablaMóviles[Cliente],"GENNEIA") -> 0 | L12: =SUM(D12:K12) -> 1
B13: Pecom | C13: =SUM(D13:K13) -> 1 | D13: =COUNTIFS(TablaMóviles[Región],"UTIM NQN",TablaMóviles[Año],2017,TablaMóviles[Cliente],"PECOM") -> 0 | E13: =COUNTIFS(TablaMóviles[Región],"UTIM NQN",TablaMóviles[Año],2018,TablaMóviles[Cliente],"PECOM") -> 0 | F13: =COUNTIFS(TablaMóviles[Región],"UTIM NQN",TablaMóviles[Año],2019,TablaMóviles[Cliente],"PECOM") -> 1 | G13: =COUNTIFS(TablaMóviles[Región],"UTIM NQN",TablaMóviles[Año],2021,TablaMóviles[Cliente],"PECOM") -> 0 | H13: =COUNTIFS(TablaMóviles[Región],"UTIM NQN",TablaMóviles[Año],2022,TablaMóviles[Cliente],"PECOM") -> 0 | I13: =COUNTIFS(TablaMóviles[Región],"UTIM NQN",TablaMóviles[Año],2023,TablaMóviles[Cliente],"PECOM") -> 0 | J13: =COUNTIFS(TablaMóviles[Región],"UTIM NQN",TablaMóviles[Año],2024,TablaMóviles[Cliente],"PECOM") -> 0 | K13: =COUNTIFS(TablaMóviles[Región],"UTIM NQN",TablaMóviles[Año],2025,TablaMóviles[Cliente],"PECOM") -> 0 | L13: =SUM(D13:K13) -> 1
B14: Back Up | C14: =SUM(D14:K14) -> 9 | D14: =COUNTIFS(TablaMóviles[Región],"UTIM NQN",TablaMóviles[Año],2017,TablaMóviles[Cliente],"BACK UP") -> 3 | E14: =COUNTIFS(TablaMóviles[Región],"UTIM NQN",TablaMóviles[Año],2018,TablaMóviles[Cliente],"BACK UP") -> 2 | F14: =COUNTIFS(TablaMóviles[Región],"UTIM NQN",TablaMóviles[Año],2019,TablaMóviles[Cliente],"BACK UP") -> 2 | G14: =COUNTIFS(TablaMóviles[Región],"UTIM NQN",TablaMóviles[Año],2021,TablaMóviles[Cliente],"BACK UP") -> 0 | H14: =COUNTIFS(TablaMóviles[Región],"UTIM NQN",TablaMóviles[Año],2022,TablaMóviles[Cliente],"BACK UP") -> 0 | I14: =COUNTIFS(TablaMóviles[Región],"UTIM NQN",TablaMóviles[Año],2023,TablaMóviles[Cliente],"BACK UP") -> 2 | J14: =COUNTIFS(TablaMóviles[Región],"UTIM NQN",TablaMóviles[Año],2024,TablaMóviles[Cliente],"BACK UP") -> 0 | K14: =COUNTIFS(TablaMóviles[Región],"UTIM NQN",TablaMóviles[Año],2025,TablaMóviles[Cliente],"BACK UP") -> 0 | L14: =SUM(D14:K14) -> 9
A15: Subtotal Neuquén | C15: =SUM(C7:C14) -> 45 | D15: =SUM(D7:D14) -> 6 | E15: =SUM(E7:E14) -> 2 | F15: =SUM(F7:F14) -> 18 | G15: =SUM(G7:G14) -> 0 | H15: =SUM(H7:H14) -> 0 | I15: =SUM(I7:I14) -> 13 | J15: =SUM(J7:J14) -> 6 | ... L15: =SUM(L7:L14) -> 45
A16: San Juan | B16: Vicuña | C16: =SUM(D16:K16) -> 17 | D16: =COUNTIFS(TablaMóviles[Región],"UTIM SJ",TablaMóviles[Año],2017,TablaMóviles[Cliente],"Vicuña") -> 0 | E16: =COUNTIFS(TablaMóviles[Región],"UTIM SJ",TablaMóviles[Año],2018,TablaMóviles[Cliente],"Vicuña") -> 0 | F16: =COUNTIFS(TablaMóviles[Región],"UTIM SJ",TablaMóviles[Año],2019,TablaMóviles[Cliente],"Vicuña") -> 1 | G16: =COUNTIFS(TablaMóviles[Región],"UTIM SJ",TablaMóviles[Año],2021,TablaMóviles[Cliente],"Vicuña") -> 0 | H16: =COUNTIFS(TablaMóviles[Región],"UTIM SJ",TablaMóviles[Año],2022,TablaMóviles[Cliente],"Vicuña") -> 3 | I16: =COUNTIFS(TablaMóviles[Región],"UTIM SJ",TablaMóviles[Año],2023,TablaMóviles[Cliente],"Vicuña") -> 2 | J16: =COUNTIFS(TablaMóviles[Región],"UTIM SJ",TablaMóviles[Año],2024,TablaMóviles[Cliente],"Vicuña") -> 6 | K16: =COUNTIFS(TablaMóviles[Región],"UTIM SJ",TablaMóviles[Año],2025,TablaMóviles[Cliente],"Vicuña") -> 5 | L16: =SUM(D16:K16) -> 17
B17: Back Up | C17: =SUM(D17:K17) -> 4 | D17: =COUNTIFS(TablaMóviles[Región],"UTIM SJ",TablaMóviles[Año],2017,TablaMóviles[Cliente],"BACK UP") -> 1 | E17: =COUNTIFS(TablaMóviles[Región],"UTIM SJ",TablaMóviles[Año],2018,TablaMóviles[Cliente],"BACK UP") -> 0 | F17: =COUNTIFS(TablaMóviles[Región],"UTIM SJ",TablaMóviles[Año],2019,TablaMóviles[Cliente],"BACK UP") -> 0 | G17: =COUNTIFS(TablaMóviles[Región],"UTIM SJ",TablaMóviles[Año],2021,TablaMóviles[Cliente],"BACK UP") -> 0 | H17: =COUNTIFS(TablaMóviles[Región],"UTIM SJ",TablaMóviles[Año],2022,TablaMóviles[Cliente],"BACK UP") -> 3 | I17: =COUNTIFS(TablaMóviles[Región],"UTIM SJ",TablaMóviles[Año],2023,TablaMóviles[Cliente],"BACK UP") -> 0 | J17: =COUNTIFS(TablaMóviles[Región],"UTIM SJ",TablaMóviles[Año],2024,TablaMóviles[Cliente],"BACK UP") -> 0 | K17: =COUNTIFS(TablaMóviles[Región],"UTIM SJ",TablaMóviles[Año],2025,TablaMóviles[Cliente],"BACK UP") -> 0 | L17: =SUM(D17:K17) -> 4
B18: En Reparación | C18: =SUM(D18:K18) -> 1 | D18: =COUNTIFS(TablaMóviles[Región],"UTIM SJ",TablaMóviles[Año],D$6,TablaMóviles[Estado],"En Reparación",TablaMóviles[Cliente],"<>BACK UP",TablaMóviles[Cliente],"<>Vicuña",TablaMóviles[Cliente],"<>NGEX") -> 0 | E18: =COUNTIFS(TablaMóviles[Región],"UTIM SJ",TablaMóviles[Año],E$6,TablaMóviles[Estado],"En Reparación",TablaMóviles[Cliente],"<>BACK UP",TablaMóviles[Cliente],"<>Vicuña",TablaMóviles[Cliente],"<>NGEX") -> 0 | F18: =COUNTIFS(TablaMóviles[Región],"UTIM SJ",TablaMóviles[Año],F$6,TablaMóviles[Estado],"En Reparación",TablaMóviles[Cliente],"<>BACK UP",TablaMóviles[Cliente],"<>Vicuña",TablaMóviles[Cliente],"<>NGEX") -> 0 | G18: =COUNTIFS(TablaMóviles[Región],"UTIM SJ",TablaMóviles[Año],G$6,TablaMóviles[Estado],"En Reparación",TablaMóviles[Cliente],"<>BACK UP",TablaMóviles[Cliente],"<>Vicuña",TablaMóviles[Cliente],"<>NGEX") -> 0 | H18: =COUNTIFS(TablaMóviles[Región],"UTIM SJ",TablaMóviles[Año],H$6,TablaMóviles[Estado],"En Reparación",TablaMóviles[Cliente],"<>BACK UP",TablaMóviles[Cliente],"<>Vicuña",TablaMóviles[Cliente],"<>NGEX") -> 1 | I18: =COUNTIFS(TablaMóviles[Región],"UTIM SJ",TablaMóviles[Año],I$6,TablaMóviles[Estado],"En Reparación",TablaMóviles[Cliente],"<>BACK UP",TablaMóviles[Cliente],"<>Vicuña",TablaMóviles[Cliente],"<>NGEX") -> 0 | J18: =COUNTIFS(TablaMóviles[Región],"UTIM SJ",TablaMóviles[Año],J$6,TablaMóviles[Estado],"En Reparación",TablaMóviles[Cliente],"<>BACK UP",TablaMóviles[Cliente],"<>Vicuña",TablaMóviles[Cliente],"<>NGEX") -> 0 | K18: =COUNTIFS(TablaMóviles[Región],"UTIM SJ",TablaMóviles[Año],K$6,TablaMóviles[Estado],"En Reparación",TablaMóviles[Cliente],"<>BACK UP",TablaMóviles[Cliente],"<>Vicuña",TablaMóviles[Cliente],"<>NGEX") -> 0 | L18: =SUM(D18:K18) -> 1
A19: Subtotal San Juan | C19: =SUM(C16:C18) -> 22 | D19: =SUM(D16:D18) -> 1 | E19: =SUM(E16:E18) -> 0 | F19: =SUM(F16:F18) -> 1 | G19: =SUM(G16:G18) -> 0 | H19: =SUM(H16:H18) -> 7 | I19: =SUM(I16:I18) -> 2 | J19: =SUM(J16:J18) -> 6 | ... L19: =SUM(L16:L18) -> 22
A20: Salta | B20: Ganfeng | C20: =SUM(D20:K20) -> 4 | D20: =COUNTIFS(TablaMóviles[Región],"UTIM SALTA",TablaMóviles[Año],2017,TablaMóviles[Cliente],"Ganfeng") -> 0 | E20: =COUNTIFS(TablaMóviles[Región],"UTIM SALTA",TablaMóviles[Año],2018,TablaMóviles[Cliente],"Ganfeng") -> 0 | F20: =COUNTIFS(TablaMóviles[Región],"UTIM SALTA",TablaMóviles[Año],2019,TablaMóviles[Cliente],"Ganfeng") -> 1 | G20: =COUNTIFS(TablaMóviles[Región],"UTIM SALTA",TablaMóviles[Año],2021,TablaMóviles[Cliente],"Ganfeng") -> 0 | H20: =COUNTIFS(TablaMóviles[Región],"UTIM SALTA",TablaMóviles[Año],2022,TablaMóviles[Cliente],"Ganfeng") -> 0 | I20: =COUNTIFS(TablaMóviles[Región],"UTIM SALTA",TablaMóviles[Año],2023,TablaMóviles[Cliente],"Ganfeng") -> 2 | J20: =COUNTIFS(TablaMóviles[Región],"UTIM SALTA",TablaMóviles[Año],2024,TablaMóviles[Cliente],"Ganfeng") -> 1 | K20: =COUNTIFS(TablaMóviles[Región],"UTIM SALTA",TablaMóviles[Año],2025,TablaMóviles[Cliente],"Ganfeng") -> 0 | L20: =SUM(D20:K20) -> 4
B21: Inthegra | C21: =SUM(D21:K21) -> 1 | D21: =COUNTIFS(TablaMóviles[Región],"UTIM SALTA",TablaMóviles[Año],2017,TablaMóviles[Cliente],"INTEGRA") -> 0 | E21: =COUNTIFS(TablaMóviles[Región],"UTIM SALTA",TablaMóviles[Año],2018,TablaMóviles[Cliente],"INTEGRA") -> 0 | F21: =COUNTIFS(TablaMóviles[Región],"UTIM SALTA",TablaMóviles[Año],2019,TablaMóviles[Cliente],"INTEGRA") -> 1 | G21: =COUNTIFS(TablaMóviles[Región],"UTIM SALTA",TablaMóviles[Año],2021,TablaMóviles[Cliente],"INTEGRA") -> 0 | H21: =COUNTIFS(TablaMóviles[Región],"UTIM SALTA",TablaMóviles[Año],2022,TablaMóviles[Cliente],"INTEGRA") -> 0 | I21: =COUNTIFS(TablaMóviles[Región],"UTIM SALTA",TablaMóviles[Año],2023,TablaMóviles[Cliente],"INTEGRA") -> 0 | J21: =COUNTIFS(TablaMóviles[Región],"UTIM SALTA",TablaMóviles[Año],2024,TablaMóviles[Cliente],"INTEGRA") -> 0 | K21: =COUNTIFS(TablaMóviles[Región],"UTIM SALTA",TablaMóviles[Año],2025,TablaMóviles[Cliente],"INTEGRA") -> 0 | L21: =SUM(D21:K21) -> 1
B22: Hannaq | C22: =SUM(D22:K22) -> 1 | D22: =COUNTIFS(TablaMóviles[Región],"UTIM SALTA",TablaMóviles[Año],D$6,TablaMóviles[Cliente],"HANNAQ") -> 0 | E22: =COUNTIFS(TablaMóviles[Región],"UTIM SALTA",TablaMóviles[Año],E$6,TablaMóviles[Cliente],"HANNAQ") -> 0 | F22: =COUNTIFS(TablaMóviles[Región],"UTIM SALTA",TablaMóviles[Año],F$6,TablaMóviles[Cliente],"HANNAQ") -> 0 | G22: =COUNTIFS(TablaMóviles[Región],"UTIM SALTA",TablaMóviles[Año],G$6,TablaMóviles[Cliente],"HANNAQ") -> 0 | H22: =COUNTIFS(TablaMóviles[Región],"UTIM SALTA",TablaMóviles[Año],H$6,TablaMóviles[Cliente],"HANNAQ") -> 0 | I22: =COUNTIFS(TablaMóviles[Región],"UTIM SALTA",TablaMóviles[Año],I$6,TablaMóviles[Cliente],"HANNAQ") -> 0 | J22: =COUNTIFS(TablaMóviles[Región],"UTIM SALTA",TablaMóviles[Año],J$6,TablaMóviles[Cliente],"HANNAQ") -> 0 | K22: =COUNTIFS(TablaMóviles[Región],"UTIM SALTA",TablaMóviles[Año],K$6,TablaMóviles[Cliente],"HANNAQ") -> 1 | L22: =SUM(D22:K22) -> 1
B23: Back Up | C23: =SUM(D23:K23) -> 4 | D23: =COUNTIFS(TablaMóviles[Región],"UTIM SALTA",TablaMóviles[Año],2017,TablaMóviles[Cliente],"BACK UP") -> 2 | E23: =COUNTIFS(TablaMóviles[Región],"UTIM SALTA",TablaMóviles[Año],2018,TablaMóviles[Cliente],"BACK UP") -> 0 | F23: =COUNTIFS(TablaMóviles[Región],"UTIM SALTA",TablaMóviles[Año],2019,TablaMóviles[Cliente],"BACK UP") -> 1 | G23: =COUNTIFS(TablaMóviles[Región],"UTIM SALTA",TablaMóviles[Año],2021,TablaMóviles[Cliente],"BACK UP") -> 0 | H23: =COUNTIFS(TablaMóviles[Región],"UTIM SALTA",TablaMóviles[Año],2022,TablaMóviles[Cliente],"BACK UP") -> 0 | I23: =COUNTIFS(TablaMóviles[Región],"UTIM SALTA",TablaMóviles[Año],2023,TablaMóviles[Cliente],"BACK UP") -> 0 | J23: =COUNTIFS(TablaMóviles[Región],"UTIM SALTA",TablaMóviles[Año],2024,TablaMóviles[Cliente],"BACK UP") -> 1 | K23: =COUNTIFS(TablaMóviles[Región],"UTIM SALTA",TablaMóviles[Año],2025,TablaMóviles[Cliente],"BACK UP") -> 0 | L23: =SUM(D23:K23) -> 4
A24: Subtotal Salta | C24: =SUM(C20:C23) -> 10 | D24: =SUM(D20:D23) -> 2 | E24: =SUM(E20:E23) -> 0 | F24: =SUM(F20:F23) -> 3 | G24: =SUM(G20:G23) -> 0 | H24: =SUM(H20:H23) -> 0 | I24: =SUM(I20:I23) -> 2 | J24: =SUM(J20:J23) -> 2 | ... L24: =SUM(L20:L23) -> 10
A26: TOTAL UTIM | C26: =+C15+C19+C24 -> 77 | D26: =+D15+D19+D24 -> 9 | E26: =+E15+E19+E24 -> 2 | F26: =+F15+F19+F24 -> 22 | G26: =+G15+G19+G24 -> 0 | H26: =+H15+H19+H24 -> 7 | I26: =+I15+I19+I24 -> 17 | J26: =+J15+J19+J24 -> 14 | ... L26: =+L15+L19+L24 -> 77
A28: Logística — Vehículos de traslado de personal
A29: Región | B29: Cliente / Asignación | C29: Total | D29: 2017 | E29: 2018 | F29: 2019 | G29: 2021 | H29: 2022 | I29: 2023 | J29: 2024 | K29: 2025 | L29: Total
A30: Neuquén | B30: Trasl Personal | C30: — | D30: — | E30: — | F30: — | G30: — | H30: — | I30: — | J30: — | K30: — | L30: —
B31: Trasl Personal Capex | C31: — | D31: — | E31: — | F31: — | G31: — | H31: — | I31: — | J31: — | K31: — | L31: —
B32: Trasl Personal CIPH | C32: — | D32: — | E32: — | F32: — | G32: — | H32: — | I32: — | J32: — | K32: — | L32: —
B33: Enfermeria Chocon | C33: — | D33: — | E33: — | F33: — | G33: — | H33: — | I33: — | J33: — | K33: — | L33: —
B34: Mantenimiento | C34: — | D34: — | E34: — | F34: — | G34: — | H34: — | I34: — | J34: — | K34: — | L34: —
B35: Logistica - Transporte | C35: — | D35: — | E35: — | F35: — | G35: — | H35: — | I35: — | J35: — | K35: — | L35: —
B36: Supervisores | C36: — | D36: — | E36: — | F36: — | G36: — | H36: — | I36: — | J36: — | K36: — | L36: —
B37: Gerencial | C37: — | D37: — | E37: — | F37: — | G37: — | H37: — | I37: — | J37: — | K37: — | L37: —
B38: Pañol | C38: — | D38: — | E38: — | F38: — | G38: — | H38: — | I38: — | J38: — | K38: — | L38: —
A39: Subtotal Logística Neuquén | C39: =SUM(D39:K39) -> 20 | D39: =COUNTIFS(TablaMóviles[Región],"LOGISTICA NQN",TablaMóviles[Año],D$6) -> 2 | E39: =COUNTIFS(TablaMóviles[Región],"LOGISTICA NQN",TablaMóviles[Año],E$6) -> 1 | F39: =COUNTIFS(TablaMóviles[Región],"LOGISTICA NQN",TablaMóviles[Año],F$6) -> 2 | G39: =COUNTIFS(TablaMóviles[Región],"LOGISTICA NQN",TablaMóviles[Año],G$6) -> 1 | H39: =COUNTIFS(TablaMóviles[Región],"LOGISTICA NQN",TablaMóviles[Año],H$6) -> 5 | I39: =COUNTIFS(TablaMóviles[Región],"LOGISTICA NQN",TablaMóviles[Año],I$6) -> 1 | J39: =COUNTIFS(TablaMóviles[Región],"LOGISTICA NQN",TablaMóviles[Año],J$6) -> 6 | K39: =COUNTIFS(TablaMóviles[Región],"LOGISTICA NQN",TablaMóviles[Año],K$6) -> 2 | L39: =SUM(D39:K39) -> 20
A40: San Juan | B40: Vicuña | C40: — | D40: — | E40: — | F40: — | G40: — | H40: — | I40: — | J40: — | K40: — | L40: —
B41: Ngex | C41: — | D41: — | E41: — | F41: — | G41: — | H41: — | I41: — | J41: — | K41: — | L41: —
B42: Vehiculo Guia | C42: — | D42: — | E42: — | F42: — | G42: — | H42: — | I42: — | J42: — | K42: — | L42: —
B43: Back Up | C43: — | D43: — | E43: — | F43: — | G43: — | H43: — | I43: — | J43: — | K43: — | L43: —
...

Sheet Resumen
A1: DASHBOARD — ESTADO DE MÓVILES · MAYO 2026
A2: Actualización automática: modificá hoja Datos → Fórmulas → Calcular ahora (F9)
A4: TOTAL MÓVILES | C4: ASIGNADOS | E4: DISPONIBLES | G4: BACK UP
A5: =COUNTA(Datos!$M$3:$M$111) -> 109 | C5: =COUNTIF(Datos!$M$3:$M$111,"Asignado") -> 86 | E5: =COUNTIF(Datos!$M$3:$M$111,"Disponible") -> 0 | G5: =COUNTIF(Datos!$M$3:$M$111,"Back Up") -> 17
C7: =TEXT(COUNTIF(Datos!$M$3:$M$111,"Asignado")/COUNTA(Datos!$M$3:$M$111),"0.0%")&" de la flota" -> 79% de la flota | E7: =TEXT(COUNTIF(Datos!$M$3:$M$111,"Disponible")/COUNTA(Datos!$M$3:$M$111),"0.0%")&" de la flota" -> 00% de la flota | G7: =TEXT(COUNTIF(Datos!$M$3:$M$111,"Back Up")/COUNTA(Datos!$M$3:$M$111),"0.0%")&" de la flota" -> 16% de la flota
A8: EN REPARACIÓN | C8: =COUNTIF(Datos!$M$3:$M$111,"En Reparación")&" unidades · "&TEXT(COUNTIF(Datos!$M$3:$M$111,"En Reparación")/COUNTA(Datos!$M$3:$M$111),"0.0%")&" de la flota" -> 6 unidades · 06% de la flota
A10: APERTURA POR REGIÓN OPERATIVA
A11: Región | B11: Total | C11: Asignados | D11: Disponibles | E11: Back Up | F11: En Reparación | G11: % Disponible | H11: % Ocupación
A12: UTIM NQN | B12: =COUNTIF(Datos!$A$3:$A$111,A12) -> 45 | C12: =COUNTIFS(Datos!$A$3:$A$111,A12,Datos!$M$3:$M$111,"Asignado") -> 36 | D12: =COUNTIFS(Datos!$A$3:$A$111,A12,Datos!$M$3:$M$111,"Disponible") -> 0 | E12: =COUNTIFS(Datos!$A$3:$A$111,A12,Datos!$M$3:$M$111,"Back Up") -> 6 | F12: =COUNTIFS(Datos!$A$3:$A$111,A12,Datos!$M$3:$M$111,"En Reparación") -> 3 | G12: =D12/B12 -> 0 | H12: =C12/B12 -> 0.8
A13: UTIM SJ | B13: =COUNTIF(Datos!$A$3:$A$111,A13) -> 22 | C13: =COUNTIFS(Datos!$A$3:$A$111,A13,Datos!$M$3:$M$111,"Asignado") -> 13 | D13: =COUNTIFS(Datos!$A$3:$A$111,A13,Datos!$M$3:$M$111,"Disponible") -> 0 | E13: =COUNTIFS(Datos!$A$3:$A$111,A13,Datos!$M$3:$M$111,"Back Up") -> 6 | F13: =COUNTIFS(Datos!$A$3:$A$111,A13,Datos!$M$3:$M$111,"En Reparación") -> 3 | G13: =D13/B13 -> 0 | H13: =C13/B13 -> 0.59090909
A14: UTIM SALTA | B14: =COUNTIF(Datos!$A$3:$A$111,A14) -> 10 | C14: =COUNTIFS(Datos!$A$3:$A$111,A14,Datos!$M$3:$M$111,"Asignado") -> 6 | D14: =COUNTIFS(Datos!$A$3:$A$111,A14,Datos!$M$3:$M$111,"Disponible") -> 0 | E14: =COUNTIFS(Datos!$A$3:$A$111,A14,Datos!$M$3:$M$111,"Back Up") -> 4 | F14: =COUNTIFS(Datos!$A$3:$A$111,A14,Datos!$M$3:$M$111,"En Reparación") -> 0 | G14: =D14/B14 -> 0 | H14: =C14/B14 -> 0.6
A15: PAMI | B15: =COUNTIF(Datos!$A$3:$A$111,A15) -> 3 | C15: =COUNTIFS(Datos!$A$3:$A$111,A15,Datos!$M$3:$M$111,"Asignado") -> 2 | D15: =COUNTIFS(Datos!$A$3:$A$111,A15,Datos!$M$3:$M$111,"Disponible") -> 0 | E15: =COUNTIFS(Datos!$A$3:$A$111,A15,Datos!$M$3:$M$111,"Back Up") -> 1 | F15: =COUNTIFS(Datos!$A$3:$A$111,A15,Datos!$M$3:$M$111,"En Reparación") -> 0 | G15: =D15/B15 -> 0 | H15: =C15/B15 -> 0.66666667
A16: LOGISTICA NQN | B16: =COUNTIF(Datos!$A$3:$A$111,A16) -> 20 | C16: =COUNTIFS(Datos!$A$3:$A$111,A16,Datos!$M$3:$M$111,"Asignado") -> 20 | D16: =COUNTIFS(Datos!$A$3:$A$111,A16,Datos!$M$3:$M$111,"Disponible") -> 0 | E16: =COUNTIFS(Datos!$A$3:$A$111,A16,Datos!$M$3:$M$111,"Back Up") -> 0 | F16: =COUNTIFS(Datos!$A$3:$A$111,A16,Datos!$M$3:$M$111,"En Reparación") -> 0 | G16: =D16/B16 -> 0 | H16: =C16/B16 -> 1
A17: LOGISTICA SJ | B17: =COUNTIF(Datos!$A$3:$A$111,A17) -> 6 | C17: =COUNTIFS(Datos!$A$3:$A$111,A17,Datos!$M$3:$M$111,"Asignado") -> 6 | D17: =COUNTIFS(Datos!$A$3:$A$111,A17,Datos!$M$3:$M$111,"Disponible") -> 0 | E17: =COUNTIFS(Datos!$A$3:$A$111,A17,Datos!$M$3:$M$111,"Back Up") -> 0 | F17: =COUNTIFS(Datos!$A$3:$A$111,A17,Datos!$M$3:$M$111,"En Reparación") -> 0 | G17: =D17/B17 -> 0 | H17: =C17/B17 -> 1
A18: LOGISTICA SALTA | B18: =COUNTIF(Datos!$A$3:$A$111,A18) -> 2 | C18: =COUNTIFS(Datos!$A$3:$A$111,A18,Datos!$M$3:$M$111,"Asignado") -> 2 | D18: =COUNTIFS(Datos!$A$3:$A$111,A18,Datos!$M$3:$M$111,"Disponible") -> 0 | E18: =COUNTIFS(Datos!$A$3:$A$111,A18,Datos!$M$3:$M$111,"Back Up") -> 0 | F18: =COUNTIFS(Datos!$A$3:$A$111,A18,Datos!$M$3:$M$111,"En Reparación") -> 0 | G18: =D18/B18 -> 0 | H18: =C18/B18 -> 1
A19: Alquilados | B19: =COUNTIF(Datos!$A$3:$A$111,A19) -> 1 | C19: =COUNTIFS(Datos!$A$3:$A$111,A19,Datos!$M$3:$M$111,"Asignado") -> 1 | D19: =COUNTIFS(Datos!$A$3:$A$111,A19,Datos!$M$3:$M$111,"Disponible") -> 0 | E19: =COUNTIFS(Datos!$A$3:$A$111,A19,Datos!$M$3:$M$111,"Back Up") -> 0 | F19: =COUNTIFS(Datos!$A$3:$A$111,A19,Datos!$M$3:$M$111,"En Reparación") -> 0 | G19: =D19/B19 -> 0 | H19: =C19/B19 -> 1
A20: TOTAL | B20: =SUM(B12:B19) -> 109 | C20: =SUM(C12:C19) -> 86 | D20: =SUM(D12:D19) -> 0 | E20: =SUM(E12:E19) -> 17 | F20: =SUM(F12:F19) -> 6 | G20: =D20/B20 -> 0 | H20: =C20/B20 -> 0.78899083

Sheet Datos
A1: BASE DE DATOS — MÓVILES OPERATIVOS · Actualizá esta hoja mensualmente
A2: Región | B2: Vertical | C2: N° Interno | D2: Dominio | E2: Tipo | F2: Modelo | G2: Año | H2: Habilitación | I2: Cliente | J2: Área | K2: Carácter | L2: Provincia | M2: Estado | N2: Clasificación | O2: Flota | P2: Antigüedad | Q2: Límite (años) | R2: Año Repo. Base | S2: Año Repo. Opt. | T2: Columna1 | U2: Columna2
A3: PAMI | B3: Petróleo | C3: UDEM | D3: AB310UB | E3: FURGON | F3: Boxer 350 LH 2.3 HDI Confort | G3: 2017 | H3: HABILITACION RN | I3: PAMI | L3: Río Negro | M3: Asignado | N3: Cliente Externo | O3: =IF(ISNUMBER(SEARCH("UTIM",A3)),"UTIM","Logística") -> Logística | P3: =2026-G3 -> 9 | Q3: =IF(I3="UCI","",IF(I3="VISTA OIL",5,IF(B3="Petróleo",8,IF(B3="Minería",3,10)))) -> 8 | R3: =IF(Q3="","",G3+Q3+1) -> 2026 | S3: =IF(Q3="","",IF(AND(B3="Minería",P3<=8),G3+8+1,R3)) -> 2026
A4: UTIM SALTA | B4: BackUp | C4: 180 | D4: AB097AU | E4: AMBULANCIA | F4: TOYOTA HILUX 4X4 CS DX 2.4 TDI 6 MT | G4: 2017 | H4: HABILITACION NACIONAL | I4: BACK UP | L4: Nacional/Pendiente | M4: Back Up | N4: Back Up | O4: =IF(ISNUMBER(SEARCH("UTIM",A4)),"UTIM","Logística") -> UTIM | P4: =2026-G4 -> 9 | Q4: =IF(I4="UCI","",IF(I4="VISTA OIL",5,IF(B4="Petróleo",8,IF(B4="Minería",3,10)))) -> 10 | R4: =IF(Q4="","",G4+Q4+1) -> 2028 | S4: =IF(Q4="","",IF(AND(B4="Minería",P4<=8),G4+8+1,R4)) -> 2028
A5: UTIM NQN | B5: OOD | C5: 215 | D5: AC329GI | E5: AMBULANCIA | F5: Toyota Hilux 4x4 2.5 TDI | G5: 2017 | H5: HABILITACION RN | I5: TECHINT | J5: Duplicar Norte | K5: Fija | L5: Río Negro | M5: Asignado | N5: Cliente Externo | O5: =IF(ISNUMBER(SEARCH("UTIM",A5)),"UTIM","Logística") -> UTIM | P5: =2026-G5 -> 9 | Q5: =IF(I5="UCI","",IF(I5="VISTA OIL",5,IF(B5="Petróleo",8,IF(B5="Minería",3,10)))) -> 10 | R5: =IF(Q5="","",G5+Q5+1) -> 2028 | S5: =IF(Q5="","",IF(AND(B5="Minería",P5<=8),G5+8+1,R5)) -> 2028
A6: UTIM NQN | B6: Petróleo | C6: 188 | D6: AB960ZM | E6: AMBULANCIA | F6: Toyota Hilux 4x4 2.5 TDI | G6: 2017 | H6: HABILITACION NEUQUEN | I6: BACK UP | J6: CAMBIO AC329GK | L6: Neuquén | M6: En Reparación | N6: En Reparación | O6: =IF(ISNUMBER(SEARCH("UTIM",A6)),"UTIM","Logística") -> UTIM | P6: =2026-G6 -> 9 | Q6: =IF(I6="UCI","",IF(I6="VISTA OIL",5,IF(B6="Petróleo",8,IF(B6="Minería",3,10)))) -> 8 | R6: =IF(Q6="","",G6+Q6+1) -> 2026 | S6: =IF(Q6="","",IF(AND(B6="Minería",P6<=8),G6+8+1,R6)) -> 2026 | T6: Disponible? | U6: Taller
A7: UTIM NQN | B7: BackUp | C7: 190 | D7: AB960ZO | E7: AMBULANCIA | F7: Ford Ranger 4x4 2.2L | G7: 2017 | H7: HABILITACION NEUQUEN | I7: BACK UP | J7: OK, NO USAR POR FALTA DE HABILITACION | L7: Neuquén | M7: En Reparación | N7: En Reparación | O7: =IF(ISNUMBER(SEARCH("UTIM",A7)),"UTIM","Logística") -> UTIM | P7: =2026-G7 -> 9 | Q7: =IF(I7="UCI","",IF(I7="VISTA OIL",5,IF(B7="Petróleo",8,IF(B7="Minería",3,10)))) -> 10 | R7: =IF(Q7="","",G7+Q7+1) -> 2028 | S7: =IF(Q7="","",IF(AND(B7="Minería",P7<=8),G7+8+1,R7)) -> 2028 | T7: No está habilitada? | U7: No tiene habilitacion
A8: UTIM NQN | B8: OOD | C8: 189 | D8: AB960ZN | E8: AMBULANCIA | F8: Toyota Hilux 4x4 2.5 TDI | G8: 2017 | H8: HABILITACION NEUQUEN | I8: TECHINT | J8: Duplicar Norte | K8: Fija | L8: Neuquén | M8: Asignado | N8: Cliente Externo | O8: =IF(ISNUMBER(SEARCH("UTIM",A8)),"UTIM","Logística") -> UTIM | P8: =2026-G8 -> 9 | Q8: =IF(I8="UCI","",IF(I8="VISTA OIL",5,IF(B8="Petróleo",8,IF(B8="Minería",3,10)))) -> 10 | R8: =IF(Q8="","",G8+Q8+1) -> 2028 | S8: =IF(Q8="","",IF(AND(B8="Minería",P8<=8),G8+8+1,R8)) -> 2028
A9: UTIM NQN | B9: OOD | C9: 187 | D9: AB960ZL | E9: AMBULANCIA | F9: Toyota Hilux 4x4 2.5 TDI | G9: 2017 | H9: HABILITACION NACIONAL | I9: GENNEIA | J9: PARQUE SOLAR JUNIN | L9: Nacional/Pendiente | M9: Asignado | O9: =IF(ISNUMBER(SEARCH("UTIM",A9)),"UTIM","Logística") -> UTIM | P9: =2026-G9 -> 9 | Q9: =IF(I9="UCI","",IF(I9="VISTA OIL",5,IF(B9="Petróleo",8,IF(B9="Minería",3,10)))) -> 10 | R9: =IF(Q9="","",G9+Q9+1) -> 2028 | S9: =IF(Q9="","",IF(AND(B9="Minería",P9<=8),G9+8+1,R9)) -> 2028
A10: UTIM NQN | B10: OOD | C10: 174 | D10: AA989TZ | E10: AMBULANCIA | F10: Toyota Hilux 4x4 2.5 TDI | G10: 2017 | H10: HABILITACION CHUBUT | I10: BACK UP | J10: BACK UP BUENOS AIRES | L10: Chubut | M10: Back Up | N10: Back Up | O10: =IF(ISNUMBER(SEARCH("UTIM",A10)),"UTIM","Logística") -> UTIM | P10: =2026-G10 -> 9 | Q10: =IF(I10="UCI","",IF(I10="VISTA OIL",5,IF(B10="Petróleo",8,IF(B10="Minería",3,10)))) -> 10 | R10: =IF(Q10="","",G10+Q10+1) -> 2028 | S10: =IF(Q10="","",IF(AND(B10="Minería",P10<=8),G10+8+1,R10)) -> 2028
A11: UTIM NQN | B11: OOD | C11: 222 | D11: AC434SW | E11: AMBULANCIA | F11: Ford Ranger 4x4 2.2L | G11: 2018 | H11: HABILITACION RN | I11: BACK UP | J11: BACK UP BAHIA BLANCA | L11: Neuquén | M11: Back Up | N11: Back Up | O11: =IF(ISNUMBER(SEARCH("UTIM",A11)),"UTIM","Logística") -> UTIM | P11: =2026-G11 -> 8 | Q11: =IF(I11="UCI","",IF(I11="VISTA OIL",5,IF(B11="Petróleo",8,IF(B11="Minería",3,10)))) -> 10 | R11: =IF(Q11="","",G11+Q11+1) -> 2029 | S11: =IF(Q11="","",IF(AND(B11="Minería",P11<=8),G11+8+1,R11)) -> 2029
A12: UTIM NQN | B12: Petróleo | C12: 221 | D12: AC434SV | E12: AMBULANCIA | F12: Ford Ranger 4x4 2.2L | G12: 2018 | H12: HABILITACION NEUQUEN | I12: BACK UP | J12: INSPECCION FISCALIZACION SANIT NQN | L12: Neuquén | M12: Back Up | N12: Back Up | O12: =IF(ISNUMBER(SEARCH("UTIM",A12)),"UTIM","Logística") -> UTIM | P12: =2026-G12 -> 8 | Q12: =IF(I12="UCI","",IF(I12="VISTA OIL",5,IF(B12="Petróleo",8,IF(B12="Minería",3,10)))) -> 8 | R12: =IF(Q12="","",G12+Q12+1) -> 2027 | S12: =IF(Q12="","",IF(AND(B12="Minería",P12<=8),G12+8+1,R12)) -> 2027 | T12: Disponible? | U12: si
A13: UTIM NQN | B13: Petróleo | C13: 276 | D13: AD786XB | E13: AMBULANCIA | F13: Ford Ranger 4x4 2.2L | G13: 2019 | H13: HABILITACION RN | I13: ACONCAGUA | J13: ENTRE LOMAS | K13: Fija | L13: Río Negro | M13: Asignado | N13: Cliente Externo | O13: =IF(ISNUMBER(SEARCH("UTIM",A13)),"UTIM","Logística") -> UTIM | P13: =2026-G13 -> 7 | Q13: =IF(I13="UCI","",IF(I13="VISTA OIL",5,IF(B13="Petróleo",8,IF(B13="Minería",3,10)))) -> 8 | R13: =IF(Q13="","",G13+Q13+1) -> 2028 | S13: =IF(Q13="","",IF(AND(B13="Minería",P13<=8),G13+8+1,R13)) -> 2028
A14: UTIM NQN | B14: Petróleo | C14: 274 | D14: AD776VZ | E14: AMBULANCIA | F14: Ford Ranger 4x4 2.2L | G14: 2019 | H14: HABILITACION NEUQUEN | I14: VISTA OIL | J14: AGUILA MORA | K14: Fija | L14: Neuquén | M14: Asignado | N14: Cliente Externo | O14: =IF(ISNUMBER(SEARCH("UTIM",A14)),"UTIM","Logística") -> UTIM | P14: =2026-G14 -> 7 | Q14: =IF(I14="UCI","",IF(I14="VISTA OIL",5,IF(B14="Petróleo",8,IF(B14="Minería",3,10)))) -> 5 | R14: =IF(Q14="","",G14+Q14+1) -> 2025 | S14: =IF(Q14="","",IF(AND(B14="Minería",P14<=8),G14+8+1,R14)) -> 2025
A15: UTIM NQN | B15: Petróleo | C15: 270 | D15: AD776VS | E15: AMBULANCIA | F15: Ford Ranger 4x4 2.2L | G15: 2019 | H15: HABILITACION RN | I15: BACK UP | J15: REPARACION POR PEDIDA DE ACEITE | L15: Río Negro | M15: En Reparación | N15: En Reparación | O15: =IF(ISNUMBER(SEARCH("UTIM",A15)),"UTIM","Logística") -> UTIM | P15: =2026-G15 -> 7 | Q15: =IF(I15="UCI","",IF(I15="VISTA OIL",5,IF(B15="Petróleo",8,IF(B15="Minería",3,10)))) -> 8 | R15: =IF(Q15="","",G15+Q15+1) -> 2028 | S15: =IF(Q15="","",IF(AND(B15="Minería",P15<=8),G15+8+1,R15)) -> 2028
A16: PAMI | B16: Petróleo | C16: 264 | D16: AD776VM | E16: AMBULANCIA | F16: Ford Ranger 4x4 2.2L | G16: 2019 | H16: HABILITACION RN | I16: PAMI | J16: BACK-UP | L16: Río Negro | M16: Back Up | N16: Back Up | O16: =IF(ISNUMBER(SEARCH("UTIM",A16)),"UTIM","Logística") -> Logística | P16: =2026-G16 -> 7 | Q16: =IF(I16="UCI","",IF(I16="VISTA OIL",5,IF(B16="Petróleo",8,IF(B16="Minería",3,10)))) -> 8 | R16: =IF(Q16="","",G16+Q16+1) -> 2028 | S16: =IF(Q16="","",IF(AND(B16="Minería",P16<=8),G16+8+1,R16)) -> 2028
A17: UTIM NQN | B17: Petróleo | C17: 269 | D17: AD776VR | E17: AMBULANCIA | F17: Ford Ranger 4x4 2.2L | G17: 2019 | H17: HABILITACION NEUQUEN | I17: YPF | J17: CHACHAHUEN | K17: Fija | L17: Neuquén | M17: Asignado | N17: Cliente Externo | O17: =IF(ISNUMBER(SEARCH("UTIM",A17)),"UTIM","Logística") -> UTIM | P17: =2026-G17 -> 7 | Q17: =IF(I17="UCI","",IF(I17="VISTA OIL",5,IF(B17="Petróleo",8,IF(B17="Minería",3,10)))) -> 8 | R17: =IF(Q17="","",G17+Q17+1) -> 2028 | S17: =IF(Q17="","",IF(AND(B17="Minería",P17<=8),G17+8+1,R17)) -> 2028
A18: UTIM NQN | B18: OOD | C18: 280 | D18: AD786XI | E18: AMBULANCIA | F18: Ford Ranger 4x4 2.2L | G18: 2019 | H18: HABILITACION NEUQUEN | I18: TECHINT | J18: Duplicar Norte | K18: Fija | L18: Neuquén | M18: Asignado | N18: Cliente Externo | O18: =IF(ISNUMBER(SEARCH("UTIM",A18)),"UTIM","Logística") -> UTIM | P18: =2026-G18 -> 7 | Q18: =IF(I18="UCI","",IF(I18="VISTA OIL",5,IF(B18="Petróleo",8,IF(B18="Minería",3,10)))) -> 10 | R18: =IF(Q18="","",G18+Q18+1) -> 2030 | S18: =IF(Q18="","",IF(AND(B18="Minería",P18<=8),G18+8+1,R18)) -> 2030
A19: UTIM NQN | B19: OOD | C19: 265 | D19: AD776VN | E19: AMBULANCIA | F19: Ford Ranger 4x4 2.2L | G19: 2019 | H19: HABILITACION NACIONAL | I19: PECOM | J19: CHIVILCOY | L19: Nacional/Pendiente | M19: Asignado | N19: Cliente Externo | O19: =IF(ISNUMBER(SEARCH("UTIM",A19)),"UTIM","Logística") -> UTIM | P19: =2026-G19 -> 7 | Q19: =IF(I19="UCI","",IF(I19="VISTA OIL",5,IF(B19="Petróleo",8,IF(B19="Minería",3,10)))) -> 10 | R19: =IF(Q19="","",G19+Q19+1) -> 2030 | S19: =IF(Q19="","",IF(AND(B19="Minería",P19<=8),G19+8+1,R19)) -> 2030
A20: UTIM NQN | B20: Petróleo | C20: 271 | D20: AD776VT | E20: AMBULANCIA | F20: Ford Ranger 4x4 2.2L | G20: 2019 | H20: HABILITACION NEUQUEN | I20: YPF | J20: BAJO DEL TORO | K20: Fija | L20: Neuquén | M20: Asignado | N20: Cliente Externo | O20: =IF(ISNUMBER(SEARCH("UTIM",A20)),"UTIM","Logística") -> UTIM | P20: =2026-G20 -> 7 | Q20: =IF(I20="UCI","",IF(I20="VISTA OIL",5,IF(B20="Petróleo",8,IF(B20="Minería",3,10)))) -> 8 | R20: =IF(Q20="","",G20+Q20+1) -> 2028 | S20: =IF(Q20="","",IF(AND(B20="Minería",P20<=8),G20+8+1,R20)) -> 2028
A21: UTIM NQN | B21: Petróleo | C21: 266 | D21: AD776VO | E21: AMBULANCIA | F21: Ford Ranger 4x4 2.2L | G21: 2019 | H21: HABILITACION NEUQUEN | I21: YPF | J21: PTG TEX - LLL | K21: Fija | L21: Neuquén | M21: Asignado | N21: Cliente Externo | O21: =IF(ISNUMBER(SEARCH("UTIM",A21)),"UTIM","Logística") -> UTIM | P21: =2026-G21 -> 7 | Q21: =IF(I21="UCI","",IF(I21="VISTA OIL",5,IF(B21="Petróleo",8,IF(B21="Minería",3,10)))) -> 8 | R21: =IF(Q21="","",G21+Q21+1) -> 2028 | S21: =IF(Q21="","",IF(AND(B21="Minería",P21<=8),G21+8+1,R21)) -> 2028
A22: UTIM NQN | B22: Petróleo | C22: 268 | D22: AD776VQ | E22: AMBULANCIA | F22: Ford Ranger 4x4 2.2L | G22: 2019 | H22: HABILITACION NEUQUEN | I22: YPF | J22: SIERRA BARROSA | K22: Fija | L22: Neuquén | M22: Asignado | N22: Cliente Externo | O22: =IF(ISNUMBER(SEARCH("UTIM",A22)),"UTIM","Logística") -> UTIM | P22: =2026-G22 -> 7 | Q22: =IF(I22="UCI","",IF(I22="VISTA OIL",5,IF(B22="Petróleo",8,IF(B22="Minería",3,10)))) -> 8 | R22: =IF(Q22="","",G22+Q22+1) -> 2028 | S22: =IF(Q22="","",IF(AND(B22="Minería",P22<=8),G22+8+1,R22)) -> 2028
A23: UTIM NQN | B23: Petróleo | C23: 282 | D23: AD786XK | E23: AMBULANCIA | F23: Ford Ranger 4x4 2.2L | G23: 2019 | H23: HABILITACION NEUQUEN | I23: YPF | J23: RIO NEUQUEN | K23: Fija | L23: Neuquén | M23: Asignado | N23: Cliente Externo | O23: =IF(ISNUMBER(SEARCH("UTIM",A23)),"UTIM","Logística") -> UTIM | P23: =2026-G23 -> 7 | Q23: =IF(I23="UCI","",IF(I23="VISTA OIL",5,IF(B23="Petróleo",8,IF(B23="Minería",3,10)))) -> 8 | R23: =IF(Q23="","",G23+Q23+1) -> 2028 | S23: =IF(Q23="","",IF(AND(B23="Minería",P23<=8),G23+8+1,R23)) -> 2028
A24: UTIM NQN | B24: Petróleo | C24: 275 | D24: AD786XA | E24: AMBULANCIA | F24: Ford Ranger 4x4 2.2L | G24: 2019 | H24: HABILITACION NEUQUEN | I24: YPF | J24: EL OCTOGONO | K24: Fija | L24: Neuquén | M24: Asignado | N24: Cliente Externo | O24: =IF(ISNUMBER(SEARCH("UTIM",A24)),"UTIM","Logística") -> UTIM | P24: =2026-G24 -> 7 | Q24: =IF(I24="UCI","",IF(I24="VISTA OIL",5,IF(B24="Petróleo",8,IF(B24="Minería",3,10)))) -> 8 | R24: =IF(Q24="","",G24+Q24+1) -> 2028 | S24: =IF(Q24="","",IF(AND(B24="Minería",P24<=8),G24+8+1,R24)) -> 2028
A25: UTIM NQN | B25: Petróleo | C25: 267 | D25: AD776VP | E25: AMBULANCIA | F25: Ford Ranger 4x4 2.2L | G25: 2019 | H25: HABILITACION NEUQUEN | I25: YPF | J25: PUESTO HERNANDEZ | K25: Fija | L25: Neuquén | M25: Asignado | N25: Cliente Externo | O25: =IF(ISNUMBER(SEARCH("UTIM",A25)),"UTIM","Logística") -> UTIM | P25: =2026-G25 -> 7 | Q25: =IF(I25="UCI","",IF(I25="VISTA OIL",5,IF(B25="Petróleo",8,IF(B25="Minería",3,10)))) -> 8 | R25: =IF(Q25="","",G25+Q25+1) -> 2028 | S25: =IF(Q25="","",IF(AND(B25="Minería",P25<=8),G25+8+1,R25)) -> 2028
A26: UTIM NQN | B26: OOD | C26: 272 | D26: AD776VU | E26: AMBULANCIA | F26: Ford Ranger 4x4 2.2L | G26: 2019 | H26: HABILITACION NEUQUEN | I26: TECHINT | J26: Duplicar Norte | K26: Fija | L26: Neuquén | M26: Asignado | N26: Cliente Externo | O26: =IF(ISNUMBER(SEARCH("UTIM",A26)),"UTIM","Logística") -> UTIM | P26: =2026-G26 -> 7 | Q26: =IF(I26="UCI","",IF(I26="VISTA OIL",5,IF(B26="Petróleo",8,IF(B26="Minería",3,10)))) -> 10 | R26: =IF(Q26="","",G26+Q26+1) -> 2030 | S26: =IF(Q26="","",IF(AND(B26="Minería",P26<=8),G26+8+1,R26)) -> 2030
A27: UTIM NQN | B27: Petróleo | C27: 273 | D27: AD776VY | E27: AMBULANCIA | F27: Ford Ranger 4x4 2.2L | G27: 2019 | H27: HABILITACION NEUQUEN | I27: YPF | J27: TRATAYEN - LC 339-2 MASE 16 | K27: Eventual | L27: Neuquén | M27: Asignado | N27: Cliente Externo | O27: =IF(ISNUMBER(SEARCH("UTIM",A27)),"UTIM","Logística") -> UTIM | P27: =2026-G27 -> 7 | Q27: =IF(I27="UCI","",IF(I27="VISTA OIL",5,IF(B27="Petróleo",8,IF(B27="Minería",3,10)))) -> 8 | R27: =IF(Q27="","",G27+Q27+1) -> 2028 | S27: =IF(Q27="","",IF(AND(B27="Minería",P27<=8),G27+8+1,R27)) -> 2028
A28: UTIM NQN | B28: Petróleo | C28: 283 | D28: AD786XL | E28: AMBULANCIA | F28: Ford Ranger 4x4 2.2L | G28: 2019 | H28: HABILITACION RN | I28: YPF | J28: SEÑAL PICADA | K28: Fija | L28: Río Negro | M28: Asignado | N28: Cliente Externo | O28: =IF(ISNUMBER(SEARCH("UTIM",A28)),"UTIM","Logística") -> UTIM | P28: =2026-G28 -> 7 | Q28: =IF(I28="UCI","",IF(I28="VISTA OIL",5,IF(B28="Petróleo",8,IF(B28="Minería",3,10)))) -> 8 | R28: =IF(Q28="","",G28+Q28+1) -> 2028 | S28: =IF(Q28="","",IF(AND(B28="Minería",P28<=8),G28+8+1,R28)) -> 2028
A29: UTIM NQN | B29: Petróleo | C29: 277 | D29: AD786XC | E29: AMBULANCIA | F29: Ford Ranger 4x4 2.2L | G29: 2019 | H29: HABILITACION NEUQUEN | I29: YPF | J29: LAJE - DLS 166 PAD 31 | K29: Eventual | L29: Neuquén | M29: Asignado | N29: Cliente Externo | O29: =IF(ISNUMBER(SEARCH("UTIM",A29)),"UTIM","Logística") -> UTIM | P29: =2026-G29 -> 7 | Q29: =IF(I29="UCI","",IF(I29="VISTA OIL",5,IF(B29="Petróleo",8,IF(B29="Minería",3,10)))) -> 8 | R29: =IF(Q29="","",G29+Q29+1) -> 2028 | S29: =IF(Q29="","",IF(AND(B29="Minería",P29<=8),G29+8+1,R29)) -> 2028
A30: UTIM NQN | B30: Petróleo | C30: 286 | D30: AD786XX | E30: AMBULANCIA | F30: Ford Ranger 4x4 2.2L | G30: 2019 | H30: HAB NQN Y RN | I30: BACK UP | J30: INSPECCION FISCALIZACION SANIT NQN | L30: Neuquén | M30: Back Up | N30: Back Up | O30: =IF(ISNUMBER(SEARCH("UTIM",A30)),"UTIM","Logística") -> UTIM | P30: =2026-G30 -> 7 | Q30: =IF(I30="UCI","",IF(I30="VISTA OIL",5,IF(B30="Petróleo",8,IF(B30="Minería",3,10)))) -> 8 | R30: =IF(Q30="","",G30+Q30+1) -> 2028 | S30: =IF(Q30="","",IF(AND(B30="Minería",P30<=8),G30+8+1,R30)) -> 2028
A31: UTIM NQN | B31: Petróleo | C31: 287 | D31: AD786XY | E31: AMBULANCIA | F31: Ford Ranger 4x4 2.2L | G31: 2019 | H31: HABILITACION NEUQUEN | I31: YPF | J31: LA ANGOSTURA SUR | K31: Eventual | L31: Neuquén | M31: Asignado | N31: Cliente Externo | O31: =IF(ISNUMBER(SEARCH("UTIM",A31)),"UTIM","Logística") -> UTIM | P31: =2026-G31 -> 7 | Q31: =IF(I31="UCI","",IF(I31="VISTA OIL",5,IF(B31="Petróleo",8,IF(B31="Minería",3,10)))) -> 8 | R31: =IF(Q31="","",G31+Q31+1) -> 2028 | S31: =IF(Q31="","",IF(AND(B31="Minería",P31<=8),G31+8+1,R31)) -> 2028
A32: UTIM NQN | B32: Petróleo | C32: 399 | D32: AF975MS | E32: AMBULANCIA | F32: TOYOTA HILUX 4X4 CC DX 2.4 TDI 6 MT | G32: 2023 | H32: HABILITACION NEUQUEN | I32: YPF | J32: EL OREJANO | K32: Fija | L32: Neuquén | M32: Asignado | N32: Cliente Externo | O32: =IF(ISNUMBER(SEARCH("UTIM",A32)),"UTIM","Logística") -> UTIM | P32: =2026-G32 -> 3 | Q32: =IF(I32="UCI","",IF(I32="VISTA OIL",5,IF(B32="Petróleo",8,IF(B32="Minería",3,10)))) -> 8 | R32: =IF(Q32="","",G32+Q32+1) -> 2032 | S32: =IF(Q32="","",IF(AND(B32="Minería",P32<=8),G32+8+1,R32)) -> 2032
A33: UTIM NQN | B33: Petróleo | C33: 413 | D33: AG054TD | E33: AMBULANCIA | F33: TOYOTA HILUX 4X4 CS DX 2.4 TDI 6 MT | G33: 2023 | H33: HAB NQN Y RN | I33: BACK UP | L33: Neuquén | M33: Back Up | N33: Back Up | O33: =IF(ISNUMBER(SEARCH("UTIM",A33)),"UTIM","Logística") -> UTIM | P33: =2026-G33 -> 3 | Q33: =IF(I33="UCI","",IF(I33="VISTA OIL",5,IF(B33="Petróleo",8,IF(B33="Minería",3,10)))) -> 8 | R33: =IF(Q33="","",G33+Q33+1) -> 2032 | S33: =IF(Q33="","",IF(AND(B33="Minería",P33<=8),G33+8+1,R33)) -> 2032
A34: UTIM NQN | B34: Petróleo | C34: 412 | D34: AG054TC | E34: AMBULANCIA | F34: TOYOTA HILUX 4X4 CS DX 2.4 TDI 6 MT | G34: 2023 | H34: HAB NQN Y RN | I34: YPF | J34: EPF LACH CENTRO | K34: Fija | L34: Neuquén | M34: Asignado | N34: Cliente Externo | O34: =IF(ISNUMBER(SEARCH("UTIM",A34)),"UTIM","Logística") -> UTIM | P34: =2026-G34 -> 3 | Q34: =IF(I34="UCI","",IF(I34="VISTA OIL",5,IF(B34="Petróleo",8,IF(B34="Minería",3,10)))) -> 8 | R34: =IF(Q34="","",G34+Q34+1) -> 2032 | S34: =IF(Q34="","",IF(AND(B34="Minería",P34<=8),G34+8+1,R34)) -> 2032
A35: UTIM NQN | B35: Petróleo | C35: 398 | D35: AG225CI | E35: AMBULANCIA | F35: TOYOTA HILUX 4X4 CC DX 2.4 TDI 6 MT | G35: 2023 | H35: HABILITACION NEUQUEN | I35: YPF | J35: AGUADA LA ARENA | K35: Fija | L35: Neuquén | M35: Asignado | N35: Cliente Externo | O35: =IF(ISNUMBER(SEARCH("UTIM",A35)),"UTIM","Logística") -> UTIM | P35: =2026-G35 -> 3 | Q35: =IF(I35="UCI","",IF(I35="VISTA OIL",5,IF(B35="Petróleo",8,IF(B35="Minería",3,10)))) -> 8 | R35: =IF(Q35="","",G35+Q35+1) -> 2032 | S35: =IF(Q35="","",IF(AND(B35="Minería",P35<=8),G35+8+1,R35)) -> 2032
A36: UTIM NQN | B36: Petróleo | C36: 394 | D36: AF975MR | E36: AMBULANCIA | F36: TOYOTA HILUX 4X4 CC DX 2.4 TDI 6 MT | G36: 2023 | H36: HABILITACION NEUQUEN | I36: YPF | J36: LA RIBERA GCIA TPF | K36: Fija | L36: Neuquén | M36: Asignado | N36: Cliente Externo | O36: =IF(ISNUMBER(SEARCH("UTIM",A36)),"UTIM","Logística") -> UTIM | P36: =2026-G36 -> 3 | Q36: =IF(I36="UCI","",IF(I36="VISTA OIL",5,IF(B36="Petróleo",8,IF(B36="Minería",3,10)))) -> 8 | R36: =IF(Q36="","",G36+Q36+1) -> 2032 | S36: =IF(Q36="","",IF(AND(B36="Minería",P36<=8),G36+8+1,R36)) -> 2032
A37: UTIM NQN | B37: Petróleo | C37: 400 | D37: AF975MU | E37: AMBULANCIA | F37: TOYOTA HILUX 4X4 CC DX 2.4 TDI 6 MT | G37: 2023 | H37: HABILITACION NEUQUEN | I37: YPF | J37: GERENCIA NOC | K37: Fija | L37: Neuquén | M37: Asignado | N37: Cliente Externo | O37: =IF(ISNUMBER(SEARCH("UTIM",A37)),"UTIM","Logística") -> UTIM | P37: =2026-G37 -> 3 | Q37: =IF(I37="UCI","",IF(I37="VISTA OIL",5,IF(B37="Petróleo",8,IF(B37="Minería",3,10)))) -> 8 | R37: =IF(Q37="","",G37+Q37+1) -> 2032 | S37: =IF(Q37="","",IF(AND(B37="Minería",P37<=8),G37+8+1,R37)) -> 2032
A38: UTIM NQN | B38: Petróleo | C38: 395 | D38: AF975MT | E38: AMBULANCIA | F38: TOYOTA HILUX 4X4 CC DX 2.4 TDI 6 MT | G38: 2023 | H38: HABILITACION NEUQUEN | I38: YPF | J38: RINCON DEL MANGRULLO | K38: Fija | L38: Neuquén | M38: Asignado | N38: Cliente Externo | O38: =IF(ISNUMBER(SEARCH("UTIM",A38)),"UTIM","Logística") -> UTIM | P38: =2026-G38 -> 3 | Q38: =IF(I38="UCI","",IF(I38="VISTA OIL",5,IF(B38="Petróleo",8,IF(B38="Minería",3,10)))) -> 8 | R38: =IF(Q38="","",G38+Q38+1) -> 2032 | S38: =IF(Q38="","",IF(AND(B38="Minería",P38<=8),G38+8+1,R38)) -> 2032
A39: UTIM NQN | B39: Petróleo | C39: 423 | D39: AG395BW | E39: AMBULANCIA | F39: HILUX 4X4 C/S DX 2.4 TDI 6 M/T | G39: 2023 | H39: HABILITACION NEUQUEN | I39: YPF | J39: REFINERIA CIPH | K39: Fija | L39: Neuquén | M39: Asignado | N39: Cliente Externo | O39: =IF(ISNUMBER(SEARCH("UTIM",A39)),"UTIM","Logística") -> UTIM | P39: =2026-G39 -> 3 | Q39: =IF(I39="UCI","",IF(I39="VISTA OIL",5,IF(B39="Petróleo",8,IF(B39="Minería",3,10)))) -> 8 | R39: =IF(Q39="","",G39+Q39+1) -> 2032 | S39: =IF(Q39="","",IF(AND(B39="Minería",P39<=8),G39+8+1,R39)) -> 2032
A40: UTIM NQN | B40: Petróleo | C40: 370 | D40: AF683IU | E40: AMBULANCIA | F40: YX.NUEVA RANGER CS 4X4 XL 2.2L D | G40: 2023 | H40: HABILITACION NEUQUEN | I40: YPF | J40: LOMA CAMPANA ESTE / PLANTA DE ARENA | K40: Fija | L40: Neuquén | M40: Asignado | N40: Cliente Externo | O40: =IF(ISNUMBER(SEARCH("UTIM",A40)),"UTIM","Logística") -> UTIM | P40: =2026-G40 -> 3 | Q40: =IF(I40="UCI","",IF(I40="VISTA OIL",5,IF(B40="Petróleo",8,IF(B40="Minería",3,10)))) -> 8 | R40: =IF(Q40="","",G40+Q40+1) -> 2032 | S40: =IF(Q40="","",IF(AND(B40="Minería",P40<=8),G40+8+1,R40)) -> 2032
...

Sheet Análisis por sector
A1: ANÁLISIS CRUZADO — MÓVILES POR DIMENSIÓN
A3: POR AÑO DE PATENTAMIENTO
A4: Valor | B4: Total | C4: Asignado | D4: Disponible | E4: Back Up | F4: En Reparación | G4: % Disp.
A5: 2017 | B5: =COUNTIF(TablaMóviles[Año],$A5) -> 13 | C5: =COUNTIFS(TablaMóviles[Año],$A5,TablaMóviles[Estado],C$4) -> 7 | D5: =COUNTIFS(TablaMóviles[Año],$A5,TablaMóviles[Estado],D$4) -> 0 | E5: =COUNTIFS(TablaMóviles[Año],$A5,TablaMóviles[Estado],E$4) -> 3 | F5: =COUNTIFS(TablaMóviles[Año],$A5,TablaMóviles[Estado],F$4) -> 3 | G5: =IFERROR(D5/B5,0) -> 0
A6: 2018 | B6: =COUNTIF(TablaMóviles[Año],$A6) -> 3 | C6: =COUNTIFS(TablaMóviles[Año],$A6,TablaMóviles[Estado],C$4) -> 1 | D6: =COUNTIFS(TablaMóviles[Año],$A6,TablaMóviles[Estado],D$4) -> 0 | E6: =COUNTIFS(TablaMóviles[Año],$A6,TablaMóviles[Estado],E$4) -> 2 | F6: =COUNTIFS(TablaMóviles[Año],$A6,TablaMóviles[Estado],F$4) -> 0 | G6: =IFERROR(D6/B6,0) -> 0
A7: 2019 | B7: =COUNTIF(TablaMóviles[Año],$A7) -> 26 | C7: =COUNTIFS(TablaMóviles[Año],$A7,TablaMóviles[Estado],C$4) -> 21 | D7: =COUNTIFS(TablaMóviles[Año],$A7,TablaMóviles[Estado],D$4) -> 0 | E7: =COUNTIFS(TablaMóviles[Año],$A7,TablaMóviles[Estado],E$4) -> 4 | F7: =COUNTIFS(TablaMóviles[Año],$A7,TablaMóviles[Estado],F$4) -> 1 | G7: =IFERROR(D7/B7,0) -> 0
A8: 2021 | B8: =COUNTIF(TablaMóviles[Año],$A8) -> 1 | C8: =COUNTIFS(TablaMóviles[Año],$A8,TablaMóviles[Estado],C$4) -> 1 | D8: =COUNTIFS(TablaMóviles[Año],$A8,TablaMóviles[Estado],D$4) -> 0 | E8: =COUNTIFS(TablaMóviles[Año],$A8,TablaMóviles[Estado],E$4) -> 0 | F8: =COUNTIFS(TablaMóviles[Año],$A8,TablaMóviles[Estado],F$4) -> 0 | G8: =IFERROR(D8/B8,0) -> 0
A9: 2022 | B9: =COUNTIF(TablaMóviles[Año],$A9) -> 15 | C9: =COUNTIFS(TablaMóviles[Año],$A9,TablaMóviles[Estado],C$4) -> 11 | D9: =COUNTIFS(TablaMóviles[Año],$A9,TablaMóviles[Estado],D$4) -> 0 | E9: =COUNTIFS(TablaMóviles[Año],$A9,TablaMóviles[Estado],E$4) -> 2 | F9: =COUNTIFS(TablaMóviles[Año],$A9,TablaMóviles[Estado],F$4) -> 2 | G9: =IFERROR(D9/B9,0) -> 0
A10: 2023 | B10: =COUNTIF(TablaMóviles[Año],$A10) -> 19 | C10: =COUNTIFS(TablaMóviles[Año],$A10,TablaMóviles[Estado],C$4) -> 17 | D10: =COUNTIFS(TablaMóviles[Año],$A10,TablaMóviles[Estado],D$4) -> 0 | E10: =COUNTIFS(TablaMóviles[Año],$A10,TablaMóviles[Estado],E$4) -> 2 | F10: =COUNTIFS(TablaMóviles[Año],$A10,TablaMóviles[Estado],F$4) -> 0 | G10: =IFERROR(D10/B10,0) -> 0
A11: 2024 | B11: =COUNTIF(TablaMóviles[Año],$A11) -> 21 | C11: =COUNTIFS(TablaMóviles[Año],$A11,TablaMóviles[Estado],C$4) -> 20 | D11: =COUNTIFS(TablaMóviles[Año],$A11,TablaMóviles[Estado],D$4) -> 0 | E11: =COUNTIFS(TablaMóviles[Año],$A11,TablaMóviles[Estado],E$4) -> 1 | F11: =COUNTIFS(TablaMóviles[Año],$A11,TablaMóviles[Estado],F$4) -> 0 | G11: =IFERROR(D11/B11,0) -> 0
A12: 2025 | B12: =COUNTIF(TablaMóviles[Año],$A12) -> 11 | C12: =COUNTIFS(TablaMóviles[Año],$A12,TablaMóviles[Estado],C$4) -> 8 | D12: =COUNTIFS(TablaMóviles[Año],$A12,TablaMóviles[Estado],D$4) -> 0 | E12: =COUNTIFS(TablaMóviles[Año],$A12,TablaMóviles[Estado],E$4) -> 3 | F12: =COUNTIFS(TablaMóviles[Año],$A12,TablaMóviles[Estado],F$4) -> 0 | G12: =IFERROR(D12/B12,0) -> 0
A13: TOTAL | B13: =SUM(B5:B12) -> 109 | C13: =SUM(C5:C12) -> 86 | D13: =SUM(D5:D12) -> 0 | E13: =SUM(E5:E12) -> 17 | F13: =SUM(F5:F12) -> 6 | G13: =IFERROR(D13/B13,0) -> 0
A15: POR TIPO DE MÓVIL
A16: Valor | B16: Total | C16: Asignado | D16: Disponible | E16: Back Up | F16: En Reparación | G16: % Disp.
A17: AMBULANCIA | B17: =COUNTIF(TablaMóviles[Tipo],$A17) -> 79 | C17: =COUNTIFS(TablaMóviles[Tipo],$A17,TablaMóviles[Estado],C$16) -> 56 | D17: =COUNTIFS(TablaMóviles[Tipo],$A17,TablaMóviles[Estado],D$16) -> 0 | E17: =COUNTIFS(TablaMóviles[Tipo],$A17,TablaMóviles[Estado],E$16) -> 17 | F17: =COUNTIFS(TablaMóviles[Tipo],$A17,TablaMóviles[Estado],F$16) -> 6 | G17: =IFERROR(D17/B17,0) -> 0
A18: FURGON | B18: =COUNTIF(TablaMóviles[Tipo],$A18) -> 3 | C18: =COUNTIFS(TablaMóviles[Tipo],$A18,TablaMóviles[Estado],C$16) -> 3 | D18: =COUNTIFS(TablaMóviles[Tipo],$A18,TablaMóviles[Estado],D$16) -> 0 | E18: =COUNTIFS(TablaMóviles[Tipo],$A18,TablaMóviles[Estado],E$16) -> 0 | F18: =COUNTIFS(TablaMóviles[Tipo],$A18,TablaMóviles[Estado],F$16) -> 0 | G18: =IFERROR(D18/B18,0) -> 0
A19: LOGISTICA | B19: =COUNTIF(TablaMóviles[Tipo],$A19) -> 27 | C19: =COUNTIFS(TablaMóviles[Tipo],$A19,TablaMóviles[Estado],C$16) -> 27 | D19: =COUNTIFS(TablaMóviles[Tipo],$A19,TablaMóviles[Estado],D$16) -> 0 | E19: =COUNTIFS(TablaMóviles[Tipo],$A19,TablaMóviles[Estado],E$16) -> 0 | F19: =COUNTIFS(TablaMóviles[Tipo],$A19,TablaMóviles[Estado],F$16) -> 0 | G19: =IFERROR(D19/B19,0) -> 0
A20: TOTAL | B20: =SUM(B17:B19) -> 109 | C20: =SUM(C17:C19) -> 86 | D20: =SUM(D17:D19) -> 0 | E20: =SUM(E17:E19) -> 17 | F20: =SUM(F17:F19) -> 6 | G20: =IFERROR(D20/B20,0) -> 0
A22: POR PROVINCIA DE HABILITACIÓN
A23: Valor | B23: Total | C23: Asignado | D23: Disponible | E23: Back Up | F23: En Reparación | G23: % Disp.
A24: Buenos Aires | B24: =COUNTIF(TablaMóviles[Provincia],$A24) -> 1 | C24: =COUNTIFS(TablaMóviles[Provincia],$A24,TablaMóviles[Estado],C$23) -> 1 | D24: =COUNTIFS(TablaMóviles[Provincia],$A24,TablaMóviles[Estado],D$23) -> 0 | E24: =COUNTIFS(TablaMóviles[Provincia],$A24,TablaMóviles[Estado],E$23) -> 0 | F24: =COUNTIFS(TablaMóviles[Provincia],$A24,TablaMóviles[Estado],F$23) -> 0 | G24: =IFERROR(D24/B24,0) -> 0
A25: Chubut | B25: =COUNTIF(TablaMóviles[Provincia],$A25) -> 1 | C25: =COUNTIFS(TablaMóviles[Provincia],$A25,TablaMóviles[Estado],C$23) -> 0 | D25: =COUNTIFS(TablaMóviles[Provincia],$A25,TablaMóviles[Estado],D$23) -> 0 | E25: =COUNTIFS(TablaMóviles[Provincia],$A25,TablaMóviles[Estado],E$23) -> 1 | F25: =COUNTIFS(TablaMóviles[Provincia],$A25,TablaMóviles[Estado],F$23) -> 0 | G25: =IFERROR(D25/B25,0) -> 0
A26: Nacional/Pendiente | B26: =COUNTIF(TablaMóviles[Provincia],$A26) -> 8 | C26: =COUNTIFS(TablaMóviles[Provincia],$A26,TablaMóviles[Estado],C$23) -> 4 | D26: =COUNTIFS(TablaMóviles[Provincia],$A26,TablaMóviles[Estado],D$23) -> 0 | E26: =COUNTIFS(TablaMóviles[Provincia],$A26,TablaMóviles[Estado],E$23) -> 4 | F26: =COUNTIFS(TablaMóviles[Provincia],$A26,TablaMóviles[Estado],F$23) -> 0 | G26: =IFERROR(D26/B26,0) -> 0
A27: Neuquén | B27: =COUNTIF(TablaMóviles[Provincia],$A27) -> 36 | C27: =COUNTIFS(TablaMóviles[Provincia],$A27,TablaMóviles[Estado],C$23) -> 29 | D27: =COUNTIFS(TablaMóviles[Provincia],$A27,TablaMóviles[Estado],D$23) -> 0 | E27: =COUNTIFS(TablaMóviles[Provincia],$A27,TablaMóviles[Estado],E$23) -> 5 | F27: =COUNTIFS(TablaMóviles[Provincia],$A27,TablaMóviles[Estado],F$23) -> 2 | G27: =IFERROR(D27/B27,0) -> 0
A28: Río Negro | B28: =COUNTIF(TablaMóviles[Provincia],$A28) -> 8 | C28: =COUNTIFS(TablaMóviles[Provincia],$A28,TablaMóviles[Estado],C$23) -> 6 | D28: =COUNTIFS(TablaMóviles[Provincia],$A28,TablaMóviles[Estado],D$23) -> 0 | E28: =COUNTIFS(TablaMóviles[Provincia],$A28,TablaMóviles[Estado],E$23) -> 1 | F28: =COUNTIFS(TablaMóviles[Provincia],$A28,TablaMóviles[Estado],F$23) -> 1 | G28: =IFERROR(D28/B28,0) -> 0
A29: Salta | B29: =COUNTIF(TablaMóviles[Provincia],$A29) -> 7 | C29: =COUNTIFS(TablaMóviles[Provincia],$A29,TablaMóviles[Estado],C$23) -> 5 | D29: =COUNTIFS(TablaMóviles[Provincia],$A29,TablaMóviles[Estado],D$23) -> 0 | E29: =COUNTIFS(TablaMóviles[Provincia],$A29,TablaMóviles[Estado],E$23) -> 2 | F29: =COUNTIFS(TablaMóviles[Provincia],$A29,TablaMóviles[Estado],F$23) -> 0 | G29: =IFERROR(D29/B29,0) -> 0
A30: Salta/Jujuy | B30: =COUNTIF(TablaMóviles[Provincia],$A30) -> 2 | C30: =COUNTIFS(TablaMóviles[Provincia],$A30,TablaMóviles[Estado],C$23) -> 1 | D30: =COUNTIFS(TablaMóviles[Provincia],$A30,TablaMóviles[Estado],D$23) -> 0 | E30: =COUNTIFS(TablaMóviles[Provincia],$A30,TablaMóviles[Estado],E$23) -> 1 | F30: =COUNTIFS(TablaMóviles[Provincia],$A30,TablaMóviles[Estado],F$23) -> 0 | G30: =IFERROR(D30/B30,0) -> 0
A31: San Juan | B31: =COUNTIF(TablaMóviles[Provincia],$A31) -> 18 | C31: =COUNTIFS(TablaMóviles[Provincia],$A31,TablaMóviles[Estado],C$23) -> 12 | D31: =COUNTIFS(TablaMóviles[Provincia],$A31,TablaMóviles[Estado],D$23) -> 0 | E31: =COUNTIFS(TablaMóviles[Provincia],$A31,TablaMóviles[Estado],E$23) -> 3 | F31: =COUNTIFS(TablaMóviles[Provincia],$A31,TablaMóviles[Estado],F$23) -> 3 | G31: =IFERROR(D31/B31,0) -> 0
A32: Sin habilitación | B32: =COUNTIF(TablaMóviles[Provincia],$A32) -> 28 | C32: =COUNTIFS(TablaMóviles[Provincia],$A32,TablaMóviles[Estado],C$23) -> 28 | D32: =COUNTIFS(TablaMóviles[Provincia],$A32,TablaMóviles[Estado],D$23) -> 0 | E32: =COUNTIFS(TablaMóviles[Provincia],$A32,TablaMóviles[Estado],E$23) -> 0 | F32: =COUNTIFS(TablaMóviles[Provincia],$A32,TablaMóviles[Estado],F$23) -> 0 | G32: =IFERROR(D32/B32,0) -> 0
A33: TOTAL | B33: =SUM(B24:B32) -> 109 | C33: =SUM(C24:C32) -> 86 | D33: =SUM(D24:D32) -> 0 | E33: =SUM(E24:E32) -> 17 | F33: =SUM(F24:F32) -> 6 | G33: =IFERROR(D33/B33,0) -> 0
A35: POR MODELO DE VEHÍCULO
A36: Valor | B36: Total | C36: Asignado | D36: Disponible | E36: Back Up | F36: En Reparación | G36: % Disp.
A37: Toyota Hilux | B37: {=SUMPRODUCT(--(ISNUMBER(SEARCH("HILUX",TablaMóviles[Modelo]))+ISNUMBER(SEARCH("TOYOTA",TablaMóviles[Modelo]))>0))} -> 67 | C37: {=SUMPRODUCT(((ISNUMBER(SEARCH("HILUX",TablaMóviles[Modelo]))+ISNUMBER(SEARCH("TOYOTA",TablaMóviles[Modelo])))>0)*(TablaMóviles[Estado]=C$36))} -> 54 | D37: {=SUMPRODUCT(((ISNUMBER(SEARCH("HILUX",TablaMóviles[Modelo]))+ISNUMBER(SEARCH("TOYOTA",TablaMóviles[Modelo])))>0)*(TablaMóviles[Estado]=D$36))} -> 0 | E37: {=SUMPRODUCT(((ISNUMBER(SEARCH("HILUX",TablaMóviles[Modelo]))+ISNUMBER(SEARCH("TOYOTA",TablaMóviles[Modelo])))>0)*(TablaMóviles[Estado]=E$36))} -> 10 | F37: {=SUMPRODUCT(((ISNUMBER(SEARCH("HILUX",TablaMóviles[Modelo]))+ISNUMBER(SEARCH("TOYOTA",TablaMóviles[Modelo])))>0)*(TablaMóviles[Estado]=F$36))} -> 3 | G37: =IFERROR(D37/B37,0) -> 0
A38: Ford Ranger | B38: {=SUMPRODUCT(--((ISNUMBER(SEARCH("RANGER",TablaMóviles[Modelo]))+ISNUMBER(SEARCH("FORD",TablaMóviles[Modelo])))>0))-B41} -> 38 | C38: {=SUMPRODUCT(((ISNUMBER(SEARCH("RANGER",TablaMóviles[Modelo]))+ISNUMBER(SEARCH("FORD",TablaMóviles[Modelo])))>0)*(TablaMóviles[Estado]=C$36))-C41} -> 28 | D38: {=SUMPRODUCT(((ISNUMBER(SEARCH("RANGER",TablaMóviles[Modelo]))+ISNUMBER(SEARCH("FORD",TablaMóviles[Modelo])))>0)*(TablaMóviles[Estado]=D$36))-D41} -> 0 | E38: {=SUMPRODUCT(((ISNUMBER(SEARCH("RANGER",TablaMóviles[Modelo]))+ISNUMBER(SEARCH("FORD",TablaMóviles[Modelo])))>0)*(TablaMóviles[Estado]=E$36))-E41} -> 7 | F38: {=SUMPRODUCT(((ISNUMBER(SEARCH("RANGER",TablaMóviles[Modelo]))+ISNUMBER(SEARCH("FORD",TablaMóviles[Modelo])))>0)*(TablaMóviles[Estado]=F$36))-F41} -> 3 | G38: =IFERROR(D38/B38,0) -> 0
A39: Peugeot Boxer | B39: =COUNTIF(TablaMóviles[Modelo],"*BOXER*") -> 1 | C39: =COUNTIFS(TablaMóviles[Modelo],"*BOXER*",TablaMóviles[Estado],C$36) -> 1 | D39: =COUNTIFS(TablaMóviles[Modelo],"*BOXER*",TablaMóviles[Estado],D$36) -> 0 | E39: =COUNTIFS(TablaMóviles[Modelo],"*BOXER*",TablaMóviles[Estado],E$36) -> 0 | F39: =COUNTIFS(TablaMóviles[Modelo],"*BOXER*",TablaMóviles[Estado],F$36) -> 0 | G39: =IFERROR(D39/B39,0) -> 0
A40: Fiat (Ducato/Strada) | B40: {=SUMPRODUCT(--((ISNUMBER(SEARCH("FIAT",TablaMóviles[Modelo]))+ISNUMBER(SEARCH("DUCATO",TablaMóviles[Modelo]))+ISNUMBER(SEARCH("STRADA",TablaMóviles[Modelo])))>0))} -> 2 | C40: {=SUMPRODUCT(((ISNUMBER(SEARCH("FIAT",TablaMóviles[Modelo]))+ISNUMBER(SEARCH("DUCATO",TablaMóviles[Modelo]))+ISNUMBER(SEARCH("STRADA",TablaMóviles[Modelo])))>0)*(TablaMóviles[Estado]=C$36))} -> 2 | D40: {=SUMPRODUCT(((ISNUMBER(SEARCH("FIAT",TablaMóviles[Modelo]))+ISNUMBER(SEARCH("DUCATO",TablaMóviles[Modelo]))+ISNUMBER(SEARCH("STRADA",TablaMóviles[Modelo])))>0)*(TablaMóviles[Estado]=D$36))} -> 0 | E40: {=SUMPRODUCT(((ISNUMBER(SEARCH("FIAT",TablaMóviles[Modelo]))+ISNUMBER(SEARCH("DUCATO",TablaMóviles[Modelo]))+ISNUMBER(SEARCH("STRADA",TablaMóviles[Modelo])))>0)*(TablaMóviles[Estado]=E$36))} -> 0 | F40: {=SUMPRODUCT(((ISNUMBER(SEARCH("FIAT",TablaMóviles[Modelo]))+ISNUMBER(SEARCH("DUCATO",TablaMóviles[Modelo]))+ISNUMBER(SEARCH("STRADA",TablaMóviles[Modelo])))>0)*(TablaMóviles[Estado]=F$36))} -> 0 | G40: =IFERROR(D40/B40,0) -> 0
A41: Ford Transit | B41: =COUNTIF(TablaMóviles[Modelo],"*TRANSIT*") -> 1 | C41: =COUNTIFS(TablaMóviles[Modelo],"*TRANSIT*",TablaMóviles[Estado],C$36) -> 1 | D41: =COUNTIFS(TablaMóviles[Modelo],"*TRANSIT*",TablaMóviles[Estado],D$36) -> 0 | E41: =COUNTIFS(TablaMóviles[Modelo],"*TRANSIT*",TablaMóviles[Estado],E$36) -> 0 | F41: =COUNTIFS(TablaMóviles[Modelo],"*TRANSIT*",TablaMóviles[Estado],F$36) -> 0 | G41: =IFERROR(D41/B41,0) -> 0
A42: TOTAL | B42: =SUM(B37:B41) -> 109 | C42: =SUM(C37:C41) -> 86 | D42: =SUM(D37:D41) -> 0 | E42: =SUM(E37:E41) -> 17 | F42: =SUM(F37:F41) -> 6 | G42: =IFERROR(D42/B42,0) -> 0

Sheet Por Cliente
A1: MÓVILES POR CLIENTE — MARZO 2026
A2: Fórmulas dinámicas — se actualiza al recalcular (F9) tras modificar hoja Datos
A4: Cliente | B4: Total | C4: Asignados | D4: Disponibles | E4: Back Up | F4: En Reparación | G4: Región(es) | H4: Tipo(s) | I4: Años | J4: Clasificación | K4: Estado ref.
